
        <mujoco model="pipette_env">
            <compiler angle="degree" coordinate="local" inertiafromgeom="true"/>
            <option integrator="RK4" timestep="0.01"/>
            <default>
                <joint armature="1" damping="1" limited="true"/>
                <geom conaffinity="1" condim="3" density="100" friction="1 0.5 0.5" margin="0.002" rgba="0.8 0.6 0.4 1"/>
            </default>
            <asset>
                <texture builtin="gradient" height="100" rgb1="1 1 1" rgb2="0 0 0" type="skybox" width="100"/>
                <texture builtin="flat" height="1278" mark="cross" markrgb="1 1 1" name="texgeom" random="0.01" rgb1="0.8 0.6 0.4" rgb2="0.8 0.6 0.4" type="cube" width="127"/>
                <texture builtin="checker" height="100" name="texplane" rgb1="0 0 0" rgb2="0.8 0.8 0.8" type="2d" width="100"/>
                <material name="MatPlane" reflectance="0.5" shininess="1" specular="1" texrepeat="60 60" texture="texplane"/>
                <material name="geom" texture="texgeom" texuniform="true"/>
            </asset>
            <worldbody>
                <light cutoff="100" diffuse="1 1 1" dir="-0 0 -1.3" directional="true" exponent="1" pos="0 0 1.3" specular=".1 .1 .1"/>
                <geom conaffinity="1" condim="3" material="MatPlane" name="floor" pos="0 0 0" rgba="0.8 0.9 0.8 1" size="40 40 40" type="plane"/>
                
                <!-- Source container -->
                <body name="source" pos="0.3 0 0.05">
                    <geom name="source_geom" type="cylinder" size="0.05 0.05" rgba="0.2 0.2 0.8 0.5"/>
                    <geom name="liquid_source" type="cylinder" size="0.045 0.03" pos="0 0 0.03" rgba="0 0 1 0.5"/>
                </body>
                
                <!-- Destination container -->
                <body name="destination" pos="-0.3 0 0.05">
                    <geom name="dest_geom" type="cylinder" size="0.05 0.05" rgba="0.2 0.8 0.2 0.5"/>
                    <geom name="liquid_dest" type="cylinder" size="0.045 0.001" pos="0 0 0.001" rgba="0 0 1 0.5"/>
                </body>
                
                <!-- Pipette -->
                <body name="pipette" pos="0 0 0.3">
                    <joint name="pipette_x" type="slide" axis="1 0 0" limited="true" range="-0.5 0.5"/>
                    <joint name="pipette_y" type="slide" axis="0 1 0" limited="true" range="-0.5 0.5"/>
                    <joint name="pipette_z" type="slide" axis="0 0 1" limited="true" range="0.1 0.4"/>
                    
                    <!-- Pipette body -->
                    <geom name="pipette_body" type="cylinder" size="0.01 0.05" rgba="0.7 0.7 0.7 1"/>
                    
                    <!-- Pipette tip -->
                    <body name="tip" pos="0 0 -0.06">
                        <geom name="pipette_tip" type="cone" size="0.007 0.02" rgba="0.9 0.9 0.9 1"/>
                        
                        <!-- Plunger - represented as a site -->
                        <site name="plunger" pos="0 0 0.01" size="0.005" rgba="1 0 0 1"/>
                    </body>
                </body>
                
                <!-- Sites for visualization -->
                <site name="source_top" pos="0.3 0 0.1" size="0.01" rgba="1 0 0 1"/>
                <site name="dest_top" pos="-0.3 0 0.1" size="0.01" rgba="1 0 0 1"/>
            </worldbody>
            
            <actuator>
                <position name="pip_x" joint="pipette_x" kp="100" ctrlrange="-1 1"/>
                <position name="pip_y" joint="pipette_y" kp="100" ctrlrange="-1 1"/>
                <position name="pip_z" joint="pipette_z" kp="100" ctrlrange="-1 1"/>
                <position name="plunger" joint="pipette_x" kp="0" ctrlrange="-1 1"/> <!-- Dummy joint for plunger control -->
            </actuator>
            
            <sensor>
                <framepos name="pipette_pos" objtype="body" objname="pipette"/>
                <framepos name="tip_pos" objtype="body" objname="tip"/>
                <framepos name="source_pos" objtype="body" objname="source"/>
                <framepos name="dest_pos" objtype="body" objname="destination"/>
            </sensor>
        </mujoco>
        