<mujoco model="pipette_env">
  <compiler angle="degree"/>

  <option timestep="0.002" gravity="0 0 -9.81"/>

  <worldbody>
    <!-- PIPETTE BODY -->
    <body name="pipette" pos="0 0 0">
      <!-- Approximate hollow barrel with 4 thin boxes -->
      <geom type="box" size="0.002 0.04 0.05" pos=" 0.0025  0 0.05"/>
      <geom type="box" size="0.002 0.04 0.05" pos="-0.0025  0 0.05"/>
      <geom type="box" size="0.04 0.002 0.05" pos=" 0    0.0025 0.05"/>
      <geom type="box" size="0.04 0.002 0.05" pos=" 0   -0.0025 0.05"/>

      <!-- SLIDING PLUNGER -->
      <body name="plunger" pos="0 0 0">
        <joint name="plunger:slide" type="slide" axis="0 0 1"
               limited="true" range="0 0.08"/>
        <geom type="cylinder" size="0.0035 0.02" pos="0 0 0.06"/>
      </body>

      <!-- HOLE at the TIP (we’ll use this to detect spheres) -->
      <site name="tip_hole" type="sphere" size="0.001" pos="0 0 0.001"/>
    </body>

    <!-- SOURCE CONTAINER (just a cylinder to hold your spheres) -->
    <body name="source" pos="0.1 0 0">
      <geom type="cylinder" size="0.05 0.02" rgba="0 0 1 0.3"/>
      <!-- individual sphere bodies will be spawned by Python -->
    </body>
  </worldbody>

  <actuator>
    <!-- Plunger position actuator -->
    <position name="plunger_act" joint="plunger:slide" kp="500"/>
  </actuator>
</mujoco>
