<?xml version="1.0" encoding="utf-8"?>
<mujoco model="pipette_system">
    <compiler angle="radian" coordinate="local" meshdir="../meshes" texturedir="../textures"/>
    <option timestep="0.002" iterations="50" solver="Newton" tolerance="1e-10"/>
    
    <asset>
        <material name="well_material" rgba="0.7 0.7 0.9 1"/>
        <material name="pipette_material" rgba="0.9 0.9 0.9 1"/>
        <material name="liquid_material" rgba="0.2 0.6 1.0 0.8"/>
        <material name="arm_material" rgba="0.5 0.5 0.5 1"/>
        <material name="surface_material" rgba="0.8 0.8 0.8 1"/>
    </asset>
    
    <worldbody>
        <!-- Lighting and camera -->
        <light directional="true" diffuse=".8 .8 .8" specular=".2 .2 .2" pos="0 0 5" dir="0 0 -1"/>
        <camera name="top_view" pos="0 0 1.5" xyaxes="1 0 0 0 1 0"/>
        
        <!-- Surface with wells -->
        <body name="surface" pos="0 0 0">
            <geom type="box" size="0.4 0.4 0.01" rgba="0.8 0.8 0.8 1" material="surface_material"/>
            
            <!-- Wells arranged in a 3x3 grid -->
            <body name="well_1" pos="-0.2 -0.2 0.01">
                <geom name="well_1_geom" type="cylinder" size="0.03 0.02" material="well_material"/>
                <site name="well_1_site" pos="0 0 0" size="0.005"/>
                <!-- Liquid in the well -->
                <geom name="liquid_1" type="cylinder" size="0.028 0.01" pos="0 0 0.01" material="liquid_material"/>
            </body>
            
            <body name="well_2" pos="0 -0.2 0.01">
                <geom name="well_2_geom" type="cylinder" size="0.03 0.02" material="well_material"/>
                <site name="well_2_site" pos="0 0 0" size="0.005"/>
                <geom name="liquid_2" type="cylinder" size="0.028 0.01" pos="0 0 0.01" material="liquid_material"/>
            </body>
            
            <body name="well_3" pos="0.2 -0.2 0.01">
                <geom name="well_3_geom" type="cylinder" size="0.03 0.02" material="well_material"/>
                <site name="well_3_site" pos="0 0 0" size="0.005"/>
                <geom name="liquid_3" type="cylinder" size="0.028 0.01" pos="0 0 0.01" material="liquid_material"/>
            </body>
            
            <body name="well_4" pos="-0.2 0 0.01">
                <geom name="well_4_geom" type="cylinder" size="0.03 0.02" material="well_material"/>
                <site name="well_4_site" pos="0 0 0" size="0.005"/>
                <geom name="liquid_4" type="cylinder" size="0.028 0.01" pos="0 0 0.01" material="liquid_material"/>
            </body>
            
            <body name="well_5" pos="0 0 0.01">
                <geom name="well_5_geom" type="cylinder" size="0.03 0.02" material="well_material"/>
                <site name="well_5_site" pos="0 0 0" size="0.005"/>
                <geom name="liquid_5" type="cylinder" size="0.028 0.01" pos="0 0 0.01" material="liquid_material"/>
            </body>
            
            <body name="well_6" pos="0.2 0 0.01">
                <geom name="well_6_geom" type="cylinder" size="0.03 0.02" material="well_material"/>
                <site name="well_6_site" pos="0 0 0" size="0.005"/>
                <geom name="liquid_6" type="cylinder" size="0.028 0.01" pos="0 0 0.01" material="liquid_material"/>
            </body>
            
            <body name="well_7" pos="-0.2 0.2 0.01">
                <geom name="well_7_geom" type="cylinder" size="0.03 0.02" material="well_material"/>
                <site name="well_7_site" pos="0 0 0" size="0.005"/>
                <geom name="liquid_7" type="cylinder" size="0.028 0.01" pos="0 0 0.01" material="liquid_material"/>
            </body>
            
            <body name="well_8" pos="0 0.2 0.01">
                <geom name="well_8_geom" type="cylinder" size="0.03 0.02" material="well_material"/>
                <site name="well_8_site" pos="0 0 0" size="0.005"/>
                <geom name="liquid_8" type="cylinder" size="0.028 0.01" pos="0 0 0.01" material="liquid_material"/>
            </body>
            
            <body name="well_9" pos="0.2 0.2 0.01">
                <geom name="well_9_geom" type="cylinder" size="0.03 0.02" material="well_material"/>
                <site name="well_9_site" pos="0 0 0" size="0.005"/>
                <geom name="liquid_9" type="cylinder" size="0.028 0.01" pos="0 0 0.01" material="liquid_material"/>
            </body>
        </body>
        
        <!-- Robot arm with 3 joints -->
        <body name="base" pos="0 0 0.2">
            <joint name="base_joint" type="slide" axis="0 0 1" range="-0.1 0.5" damping="5"/>
            <geom name="base_geom" type="cylinder" size="0.05 0.02" material="arm_material"/>
            
            <body name="arm_1" pos="0 0 0.02">
                <joint name="shoulder" type="hinge" axis="0 1 0" range="-3.14 3.14" damping="1"/>
                <geom name="arm_1_geom" type="capsule" size="0.02" fromto="0 0 0 0.2 0 0" material="arm_material"/>
                
                <body name="arm_2" pos="0.2 0 0">
                    <joint name="elbow" type="hinge" axis="0 1 0" range="-3.14 3.14" damping="1"/>
                    <geom name="arm_2_geom" type="capsule" size="0.015" fromto="0 0 0 0.2 0 0" material="arm_material"/>
                    
                    <body name="wrist" pos="0.2 0 0">
                        <joint name="wrist_joint" type="ball" range="0 0.6" damping="0.5"/>
                        <geom name="wrist_geom" type="sphere" size="0.02" material="arm_material"/>
                        
                        <!-- Pipette -->
                        <body name="pipette" pos="0 0 -0.05">
                            <joint name="grip" type="hinge" axis="1 0 0" range="0 0.2" damping="0.5"/>
                            <geom name="pipette_body" type="cylinder" size="0.01 0.08" pos="0 0 -0.05" material="pipette_material"/>
                            <!-- <geom name="pipette_tip" type="cone" size="0.01 0.02" pos="0 0 -0.14" material="pipette_material"/> -->
                            
                            <!-- Plunger for the pipette -->
                            <body name="plunger" pos="0 0 0.03">
                                <joint name="plunger_joint" type="slide" axis="0 0 1" range="0 0.05" damping="10"/>
                                <geom name="plunger_geom" type="cylinder" size="0.008 0.03" material="pipette_material"/>
                                
                                <!-- Site for detecting if liquid is being held -->
                                <site name="liquid_detector" pos="0 0 -0.17" size="0.001"/>
                                
                                <!-- Liquid in pipette (initially invisible) -->
                                <geom name="pipette_liquid" type="cylinder" size="0.006 0.01" pos="0 0 -0.16" material="liquid_material" rgba="0.2 0.6 1.0 0"/>
                            </body>
                        </body>
                    </body>
                </body>
            </body>
        </body>
    </worldbody>
    
    <actuator>
        <!-- Joint actuators for the robot arm -->
        <motor name="base_control" joint="base_joint" ctrlrange="-1 1" ctrllimited="true"/>
        <motor name="shoulder_control" joint="shoulder" ctrlrange="-1 1" ctrllimited="true"/>
        <motor name="elbow_control" joint="elbow" ctrlrange="-1 1" ctrllimited="true"/>
        <motor name="wrist_control" joint="wrist_joint" ctrlrange="-1 1" ctrllimited="true"/>
        
        <!-- Pipette specific actuators -->
        <motor name="grip_control" joint="grip" ctrlrange="0 1" ctrllimited="true"/>
        <motor name="plunger_control" joint="plunger_joint" ctrlrange="0 1" ctrllimited="true"/>
    </actuator>
    
    <sensor>
        <!-- Position sensors for all joints -->
        <jointpos name="base_pos" joint="base_joint"/>
        <jointpos name="shoulder_pos" joint="shoulder"/>
        <jointpos name="elbow_pos" joint="elbow"/>
        <!-- <jointpos name="wrist_pos" joint="wrist_joint"/> -->
        <jointpos name="grip_pos" joint="grip"/>
        <jointpos name="plunger_pos" joint="plunger_joint"/>
        
        <!-- Site sensors for well positions
        <site name="well_1_sensor" site="well_1_site"/>
        <site name="well_2_sensor" site="well_2_site"/>
        <site name="well_3_sensor" site="well_3_site"/>
        <site name="well_4_sensor" site="well_4_site"/>
        <site name="well_5_sensor" site="well_5_site"/>
        <site name="well_6_sensor" site="well_6_site"/>
        <site name="well_7_sensor" site="well_7_site"/>
        <site name="well_8_sensor" site="well_8_site"/>
        <site name="well_9_sensor" site="well_9_site"/>
        
         Liquid detection sensor
        <site name="liquid_detect_sensor" site="liquid_detector"/> -->
    </sensor>
</mujoco>